[32m2024-07-25 00:34:03 -0700[0m - dagster - [34mDEBUG[0m - __ASSET_JOB - 42c3840a-a1b9-45ce-9d29-18e3d7bb8fbe - 5518 - LOGS_CAPTURED - Started capturing logs in process (pid: 5518).
[32m2024-07-25 00:34:03 -0700[0m - dagster - [34mDEBUG[0m - __ASSET_JOB - 42c3840a-a1b9-45ce-9d29-18e3d7bb8fbe - 5518 - taxi_trips - STEP_START - Started execution of step "taxi_trips".
[32m2024-07-25 00:34:03 -0700[0m - dagster - [34mERROR[0m - [31m__ASSET_JOB - 42c3840a-a1b9-45ce-9d29-18e3d7bb8fbe - 5518 - taxi_trips - STEP_FAILURE - Execution of step "taxi_trips" failed.

dagster._core.errors.DagsterExecutionStepExecutionError: Error occurred while executing op "taxi_trips"::

duckdb.duckdb.IOException: IO Error: Could not set lock on file "/Users/saarth.shah/Desktop/dagster_university/data/staging/data.duckdb": Conflicting lock is held in /Users/saarth.shah/.pyenv/versions/3.10.12/bin/python3.10 (PID 5277) by user saarth.shah. See also https://duckdb.org/docs/connect/concurrency

Stack Trace:
  File "/Users/saarth.shah/.pyenv/versions/3.10.12/lib/python3.10/site-packages/dagster/_core/execution/plan/utils.py", line 54, in op_execution_error_boundary
    yield
  File "/Users/saarth.shah/.pyenv/versions/3.10.12/lib/python3.10/site-packages/dagster/_utils/__init__.py", line 473, in iterate_with_context
    next_output = next(iterator)
  File "/Users/saarth.shah/.pyenv/versions/3.10.12/lib/python3.10/site-packages/dagster/_core/execution/plan/compute_generator.py", line 141, in _coerce_op_compute_fn_to_iterator
    result = invoke_compute_fn(
  File "/Users/saarth.shah/.pyenv/versions/3.10.12/lib/python3.10/site-packages/dagster/_core/execution/plan/compute_generator.py", line 129, in invoke_compute_fn
    return fn(context, **args_to_pass) if context_arg_provided else fn(**args_to_pass)
  File "/Users/saarth.shah/Desktop/dagster_university/dagster_university/assets/trips.py", line 55, in taxi_trips
    conn = duckdb.connect(os.getenv("DUCKDB_DATABASE"))
[0m
